Workbook

Sheet อ่านก่อน
B1: ไฟล์ 2 · ยอดตั้งต้นงบดุล แยกตามผู้ถือ
B2: กรอกยอดคงเหลือของทุกบัญชี ณ วันตัดยอด ทีละผู้ถือ — ระบบจะใช้เป็นจุดเริ่มของทุกรายงาน
B4: วันตัดยอด
B5: ใช้ 30/09/2026 ทุกชีท | C5: ถ้าสรุปไม่ทันจริงๆ เลื่อนเป็น 31/10/2026 ได้ แต่ต้องเลื่อนทั้งไฟล์พร้อมกัน ห้ามชีทละวัน
B7: กรอกอย่างไร
B8: หนึ่งชีทต่อหนึ่งผู้ถือ | C8: 6 ชีท: SRI Corporation · สุธี · ธนากร · ธนวินท์ · เบ็ญจพร · สุดจิตต์
B9: กรอกช่อง 'ยอดตั้งต้น' ช่องเดียว | C9: ใส่จำนวนบวก ไม่ต้องคิดว่าเป็นเดบิตหรือเครดิต ระบบรู้จากประเภทบัญชี · ข้อยกเว้นเดียวคือ 3300 กำไรสะสม ที่ติดลบได้ถ้าขาดทุนสะสม — ใส่ติดลบได้เลย
B10: บัญชีที่ไม่มียอด เว้นว่างไว้ | C10: ไม่ต้องใส่ 0
B11: ชีท 'รวมทุกผู้ถือ' | C11: คำนวณให้อัตโนมัติ ไม่ต้องกรอก ใช้ตรวจว่ายอดรวมกองกลางตรงกับที่ลูกพี่รู้
B13: สามข้อที่ต้องเข้าใจก่อนกรอก
A14: ! | B14: ใส่ราคาทุน ไม่ใช่ราคาประเมิน | C14: งบดุลตั้งต้นลงตามราคาทุน/ตามบัญชี · ราคาประเมินกับราคาตลาดใส่ในชีท 'ทรัพย์สิน' ของไฟล์เทมเพลตข้อมูลตั้งต้น (คอลัมน์ 'มูลค่าปัจจุบัน') ถ้าเอาราคาประเมินมาใส่ที่นี่ งบจะไม่ลงตัว เพราะยังไม่มีบัญชีส่วนเกินทุนจากการตีราคา
A15: ! | B15: เงินสดต้องแยกทีละบัญชีธนาคาร | C15: แต่ละชีทมีตารางย่อยให้กรอกยอดแต่ละบัญชี แล้วบรรทัด 1100 จะรวมให้เอง ระบบบังคับว่าทุกบรรทัดเงินสดต้องผูกบัญชีจริง (Money Invariant 2)
A16: ! | B16: แต่ละชีทต้องลงตัวในตัวเอง | C16: สินทรัพย์ − หนี้สิน − ส่วนของเจ้าของ = 0 · ช่องตรวจล่างสุดจะเป็นสีเขียวเมื่อลงตัว ถ้ายังไม่ตรง ใส่ผลต่างที่บรรทัด 'ผลต่างรอกระทบยอด' อย่าไปดัดตัวเลขอื่นให้ตรง
B18: ทำไมไม่มีบรรทัด 'เงินถอนของเจ้าของ'
B19: เงินถอนสะสมถูกหักอยู่ในกำไรสะสมแล้ว | C19: 3200 เงินถอนของเจ้าของ เป็นยอดที่เกิดระหว่างงวด ไม่ใช่ยอดคงเหลือ ณ วันตั้งต้น · ถ้าใส่เป็นอีกบรรทัดจะถูกนับสองรอบ ส่วนของเจ้าของจะบวมเท่าที่ถอนออกไป · การถอนหลังวันตัดยอดบันทึกเป็นรายการปกติในระบบ
B21: ผลต่างรอกระทบยอด
B22: ใส่ที่บรรทัด 3300 กำไรสะสม ชั่วคราว | C22: แล้วเขียนไว้ในช่องหมายเหตุว่าเป็นผลต่างเท่าไร · พอสรุปของจริงได้แล้วค่อยแยกว่า ส่วนไหนเป็นทุน (3100) ส่วนไหนเป็นเงินกู้กรรมการ (2300) แล้ว import ทับได้เลย
B24: หุ้น/กองทุน ใช้ FIFO
B25: ชีท 'พอร์ตลงทุน (รายล็อต)' | C25: FIFO ต้องรู้ว่าซื้อล็อตไหนก่อน จึงต้องกรอก **ทีละล็อต** (วันที่ซื้อ + จำนวน + ราคาต่อหน่วย) ไม่ใช่ต้นทุนเฉลี่ย · ยอดรวมของชีทนี้ต้องเท่ากับบรรทัด 1700 ในชีทของผู้ถือคนนั้น

Sheet BS-SRI Corporation
A1: ยอดตั้งต้นงบดุล — SRI Corporation
A2: ณ วันที่ 30/09/2026 · ราคาทุน/ตามบัญชี · ผู้ถือนิติบุคคล: ทุกรายการต้องมีหลักฐาน
A4: รหัส | B4: ชื่อบัญชี | C4: ฝั่ง | D4: หมวดในงบ | E4: ยอดตั้งต้น * | F4: หมายเหตุ / ที่มาของตัวเลข
E5: ใส่จำนวนบวกเสมอ · ไม่มียอดให้เว้นว่าง | F5: เช่น 'ยอด statement 30/09' หรือ 'ตามสัญญาเลขที่ ...'
A6: 1100 | B6: เงินสดและเงินฝากธนาคาร | C6: สินทรัพย์ | D6: สินทรัพย์หมุนเวียน | E6: 2000000
A7: 1200 | B7: ลูกหนี้ค่าเช่า | C7: สินทรัพย์ | D7: สินทรัพย์หมุนเวียน
A8: 1210 | B8: ลูกหนี้ดอกเบี้ย | C8: สินทรัพย์ | D8: สินทรัพย์หมุนเวียน
A9: 1600 | B9: เงินมัดจำจ่าย | C9: สินทรัพย์ | D9: สินทรัพย์หมุนเวียน
A10: 1300 | B10: เงินให้กู้ยืม - เงินต้น | C10: สินทรัพย์ | D10: เงินให้กู้และลงทุนตามสัญญา
A11: 1400 | B11: เงินลงทุนขายฝาก - เงินต้น | C11: สินทรัพย์ | D11: เงินให้กู้และลงทุนตามสัญญา | E11: 1000000
A12: 1410 | B12: เงินลงทุนจำนอง - เงินต้น | C12: สินทรัพย์ | D12: เงินให้กู้และลงทุนตามสัญญา
A13: 1500 | B13: อสังหาริมทรัพย์เพื่อการลงทุน | C13: สินทรัพย์ | D13: อสังหาริมทรัพย์เพื่อการลงทุน | E13: 5000000
A14: 1510 | B14: ค่ารีโนเวท (บันทึกเป็นทุน) | C14: สินทรัพย์ | D14: อสังหาริมทรัพย์เพื่อการลงทุน
A15: 1700 | B15: เงินลงทุนในหลักทรัพย์ | C15: สินทรัพย์ | D15: เงินลงทุน
A16: 1720 | B16: เงินลงทุนในทองคำและสินทรัพย์ทางเลือก | C16: สินทรัพย์ | D16: เงินลงทุน
A17: 1710 | B17: เงินลงทุนในบริษัทในเครือ | C17: สินทรัพย์ | D17: เงินลงทุน
A18: 1310 | B18: ลูกหนี้ระหว่างกัน (ในกองกลาง) | C18: สินทรัพย์ | D18: รายการระหว่างกัน (ตัดออกในงบรวม)
A19: 2100 | B19: เจ้าหนี้การค้า-เจ้าหนี้อื่น | C19: หนี้สิน | D19: หนี้สินหมุนเวียน
A20: 2200 | B20: เงินมัดจำรับจากผู้เช่า | C20: หนี้สิน | D20: หนี้สินหมุนเวียน
A21: 2410 | B21: เงินกู้ธนาคาร | C21: หนี้สิน | D21: เงินกู้ | E21: 3000000
A22: 2300 | B22: เงินกู้ยืมกรรมการ | C22: หนี้สิน | D22: เงินกู้
A23: 2400 | B23: เงินกู้ยืมอื่น | C23: หนี้สิน | D23: เงินกู้
A24: 2310 | B24: เจ้าหนี้ระหว่างกัน (ในกองกลาง) | C24: หนี้สิน | D24: รายการระหว่างกัน (ตัดออกในงบรวม)
A25: 3100 | B25: ทุนตั้งต้น | C25: ส่วนของเจ้าของ | D25: ส่วนของเจ้าของ | E25: 4000000
A26: 3300 | B26: กำไรสะสม | C26: ส่วนของเจ้าของ | D26: ส่วนของเจ้าของ | E26: 1000000
B28: รวมสินทรัพย์ | E28: =SUM(E6,E7,E8,E9,E10,E11,E12,E13,E14,E15,E16,E17,E18)
B29: รวมหนี้สิน | E29: =SUM(E19,E20,E21,E22,E23,E24)
B30: รวมส่วนของเจ้าของ | E30: =SUM(E25,E26)
B32: ตรวจ: สินทรัพย์ − หนี้สิน − ส่วนของเจ้าของ | E32: =E28-E29-E30 | F32: ต้องเป็น 0 — ถ้าไม่ใช่ ใส่ผลต่างที่ 3300 กำไรสะสม แล้วเขียนหมายเหตุไว้
B35: แยกยอดเงินสดตามบัญชี (ต้องรวมได้เท่าบรรทัด 1100)
B36: บัญชีที่ระบบมีอยู่แล้วเติมให้ · บัญชีใหม่กรอกในแถวว่างด้านล่าง · ทุกบาทของบรรทัด 1100 ต้องมีบัญชีรองรับ
B37: บัญชี | C37: ธนาคาร / ช่องทาง | D37: เลขท้าย | E37: ยอดตั้งต้น
B38: SRI - SCB | C38: ไทยพาณิชย์ | D38: 4412 | E38: 2000000
F40: ← บัญชีใหม่ที่ยังไม่มีในระบบ กรอกชื่อ+ธนาคาร+ยอด
F41: ← บัญชีใหม่ที่ยังไม่มีในระบบ กรอกชื่อ+ธนาคาร+ยอด
F42: ← บัญชีใหม่ที่ยังไม่มีในระบบ กรอกชื่อ+ธนาคาร+ยอด
F43: ← บัญชีใหม่ที่ยังไม่มีในระบบ กรอกชื่อ+ธนาคาร+ยอด
F44: ← บัญชีใหม่ที่ยังไม่มีในระบบ กรอกชื่อ+ธนาคาร+ยอด
F45: ← บัญชีใหม่ที่ยังไม่มีในระบบ กรอกชื่อ+ธนาคาร+ยอด
B46: รวมเงินสด | E46: =SUM(E38:E45) | F46: ต้องเท่ากับบรรทัด 1100 (แถว 6)
...

Sheet BS-สุธี
A1: ยอดตั้งต้นงบดุล — สุธี
A2: ณ วันที่ 30/09/2026 · ราคาทุน/ตามบัญชี · ถือในชื่อบุคคล แต่ยังเป็นกองกลางของครอบครัว
A4: รหัส | B4: ชื่อบัญชี | C4: ฝั่ง | D4: หมวดในงบ | E4: ยอดตั้งต้น * | F4: หมายเหตุ / ที่มาของตัวเลข
E5: ใส่จำนวนบวกเสมอ · ไม่มียอดให้เว้นว่าง | F5: เช่น 'ยอด statement 30/09' หรือ 'ตามสัญญาเลขที่ ...'
A6: 1100 | B6: เงินสดและเงินฝากธนาคาร | C6: สินทรัพย์ | D6: สินทรัพย์หมุนเวียน | E6: 300000
A7: 1200 | B7: ลูกหนี้ค่าเช่า | C7: สินทรัพย์ | D7: สินทรัพย์หมุนเวียน
A8: 1210 | B8: ลูกหนี้ดอกเบี้ย | C8: สินทรัพย์ | D8: สินทรัพย์หมุนเวียน
A9: 1600 | B9: เงินมัดจำจ่าย | C9: สินทรัพย์ | D9: สินทรัพย์หมุนเวียน
A10: 1300 | B10: เงินให้กู้ยืม - เงินต้น | C10: สินทรัพย์ | D10: เงินให้กู้และลงทุนตามสัญญา
A11: 1400 | B11: เงินลงทุนขายฝาก - เงินต้น | C11: สินทรัพย์ | D11: เงินให้กู้และลงทุนตามสัญญา
A12: 1410 | B12: เงินลงทุนจำนอง - เงินต้น | C12: สินทรัพย์ | D12: เงินให้กู้และลงทุนตามสัญญา
A13: 1500 | B13: อสังหาริมทรัพย์เพื่อการลงทุน | C13: สินทรัพย์ | D13: อสังหาริมทรัพย์เพื่อการลงทุน
A14: 1510 | B14: ค่ารีโนเวท (บันทึกเป็นทุน) | C14: สินทรัพย์ | D14: อสังหาริมทรัพย์เพื่อการลงทุน
A15: 1700 | B15: เงินลงทุนในหลักทรัพย์ | C15: สินทรัพย์ | D15: เงินลงทุน
A16: 1720 | B16: เงินลงทุนในทองคำและสินทรัพย์ทางเลือก | C16: สินทรัพย์ | D16: เงินลงทุน
A17: 1710 | B17: เงินลงทุนในบริษัทในเครือ | C17: สินทรัพย์ | D17: เงินลงทุน
A18: 1310 | B18: ลูกหนี้ระหว่างกัน (ในกองกลาง) | C18: สินทรัพย์ | D18: รายการระหว่างกัน (ตัดออกในงบรวม)
... A23: 2400 | B23: เงินกู้ยืมอื่น | C23: หนี้สิน | D23: เงินกู้
A24: 2310 | B24: เจ้าหนี้ระหว่างกัน (ในกองกลาง) | C24: หนี้สิน | D24: รายการระหว่างกัน (ตัดออกในงบรวม) | E24: 100000
A25: 3100 | B25: ทุนตั้งต้น | C25: ส่วนของเจ้าของ | D25: ส่วนของเจ้าของ | E25: 200000
A26: 3300 | B26: กำไรสะสม | C26: ส่วนของเจ้าของ | D26: ส่วนของเจ้าของ
B28: รวมสินทรัพย์ | E28: =SUM(E6,E7,E8,E9,E10,E11,E12,E13,E14,E15,E16,E17,E18)
B29: รวมหนี้สิน | E29: =SUM(E19,E20,E21,E22,E23,E24)
B30: รวมส่วนของเจ้าของ | E30: =SUM(E25,E26)
B32: ตรวจ: สินทรัพย์ − หนี้สิน − ส่วนของเจ้าของ | E32: =E28-E29-E30 | F32: ต้องเป็น 0 — ถ้าไม่ใช่ ใส่ผลต่างที่ 3300 กำไรสะสม แล้วเขียนหมายเหตุไว้
B35: แยกยอดเงินสดตามบัญชี (ต้องรวมได้เท่าบรรทัด 1100)
B36: บัญชีที่ระบบมีอยู่แล้วเติมให้ · บัญชีใหม่กรอกในแถวว่างด้านล่าง · ทุกบาทของบรรทัด 1100 ต้องมีบัญชีรองรับ
B37: บัญชี | C37: ธนาคาร / ช่องทาง | D37: เลขท้าย | E37: ยอดตั้งต้น
B38: สุธี - TTB | C38: ทหารไทยธนชาต | D38: 1174 | E38: 300000
F39: ← บัญชีใหม่ที่ยังไม่มีในระบบ กรอกชื่อ+ธนาคาร+ยอด
F40: ← บัญชีใหม่ที่ยังไม่มีในระบบ กรอกชื่อ+ธนาคาร+ยอด
F41: ← บัญชีใหม่ที่ยังไม่มีในระบบ กรอกชื่อ+ธนาคาร+ยอด
F42: ← บัญชีใหม่ที่ยังไม่มีในระบบ กรอกชื่อ+ธนาคาร+ยอด
F43: ← บัญชีใหม่ที่ยังไม่มีในระบบ กรอกชื่อ+ธนาคาร+ยอด
F44: ← บัญชีใหม่ที่ยังไม่มีในระบบ กรอกชื่อ+ธนาคาร+ยอด
B45: รวมเงินสด | E45: =SUM(E38:E44) | F45: ต้องเท่ากับบรรทัด 1100 (แถว 6)
B46: ตรวจ: ผลต่างกับบรรทัด 1100 | E46: =E45-E6

Sheet BS-ธนากร
A1: ยอดตั้งต้นงบดุล — ธนากร
A2: ณ วันที่ 30/09/2026 · ราคาทุน/ตามบัญชี · ถือในชื่อบุคคล แต่ยังเป็นกองกลางของครอบครัว
A4: รหัส | B4: ชื่อบัญชี | C4: ฝั่ง | D4: หมวดในงบ | E4: ยอดตั้งต้น * | F4: หมายเหตุ / ที่มาของตัวเลข
E5: ใส่จำนวนบวกเสมอ · ไม่มียอดให้เว้นว่าง | F5: เช่น 'ยอด statement 30/09' หรือ 'ตามสัญญาเลขที่ ...'
A6: 1100 | B6: เงินสดและเงินฝากธนาคาร | C6: สินทรัพย์ | D6: สินทรัพย์หมุนเวียน | E6: 1000000
A7: 1200 | B7: ลูกหนี้ค่าเช่า | C7: สินทรัพย์ | D7: สินทรัพย์หมุนเวียน | E7: 20000
A8: 1210 | B8: ลูกหนี้ดอกเบี้ย | C8: สินทรัพย์ | D8: สินทรัพย์หมุนเวียน
A9: 1600 | B9: เงินมัดจำจ่าย | C9: สินทรัพย์ | D9: สินทรัพย์หมุนเวียน
A10: 1300 | B10: เงินให้กู้ยืม - เงินต้น | C10: สินทรัพย์ | D10: เงินให้กู้และลงทุนตามสัญญา
A11: 1400 | B11: เงินลงทุนขายฝาก - เงินต้น | C11: สินทรัพย์ | D11: เงินให้กู้และลงทุนตามสัญญา
A12: 1410 | B12: เงินลงทุนจำนอง - เงินต้น | C12: สินทรัพย์ | D12: เงินให้กู้และลงทุนตามสัญญา
A13: 1500 | B13: อสังหาริมทรัพย์เพื่อการลงทุน | C13: สินทรัพย์ | D13: อสังหาริมทรัพย์เพื่อการลงทุน | E13: 3000000
A14: 1510 | B14: ค่ารีโนเวท (บันทึกเป็นทุน) | C14: สินทรัพย์ | D14: อสังหาริมทรัพย์เพื่อการลงทุน
A15: 1700 | B15: เงินลงทุนในหลักทรัพย์ | C15: สินทรัพย์ | D15: เงินลงทุน | E15: 300000
A16: 1720 | B16: เงินลงทุนในทองคำและสินทรัพย์ทางเลือก | C16: สินทรัพย์ | D16: เงินลงทุน
A17: 1710 | B17: เงินลงทุนในบริษัทในเครือ | C17: สินทรัพย์ | D17: เงินลงทุน
A18: 1310 | B18: ลูกหนี้ระหว่างกัน (ในกองกลาง) | C18: สินทรัพย์ | D18: รายการระหว่างกัน (ตัดออกในงบรวม) | E18: 100000
A19: 2100 | B19: เจ้าหนี้การค้า-เจ้าหนี้อื่น | C19: หนี้สิน | D19: หนี้สินหมุนเวียน
A20: 2200 | B20: เงินมัดจำรับจากผู้เช่า | C20: หนี้สิน | D20: หนี้สินหมุนเวียน
A21: 2410 | B21: เงินกู้ธนาคาร | C21: หนี้สิน | D21: เงินกู้ | E21: 500000
A22: 2300 | B22: เงินกู้ยืมกรรมการ | C22: หนี้สิน | D22: เงินกู้
A23: 2400 | B23: เงินกู้ยืมอื่น | C23: หนี้สิน | D23: เงินกู้
A24: 2310 | B24: เจ้าหนี้ระหว่างกัน (ในกองกลาง) | C24: หนี้สิน | D24: รายการระหว่างกัน (ตัดออกในงบรวม)
A25: 3100 | B25: ทุนตั้งต้น | C25: ส่วนของเจ้าของ | D25: ส่วนของเจ้าของ | E25: 2000000
A26: 3300 | B26: กำไรสะสม | C26: ส่วนของเจ้าของ | D26: ส่วนของเจ้าของ | E26: 1920000
B28: รวมสินทรัพย์ | E28: =SUM(E6,E7,E8,E9,E10,E11,E12,E13,E14,E15,E16,E17,E18)
B29: รวมหนี้สิน | E29: =SUM(E19,E20,E21,E22,E23,E24)
B30: รวมส่วนของเจ้าของ | E30: =SUM(E25,E26)
B32: ตรวจ: สินทรัพย์ − หนี้สิน − ส่วนของเจ้าของ | E32: =E28-E29-E30 | F32: ต้องเป็น 0 — ถ้าไม่ใช่ ใส่ผลต่างที่ 3300 กำไรสะสม แล้วเขียนหมายเหตุไว้
B35: แยกยอดเงินสดตามบัญชี (ต้องรวมได้เท่าบรรทัด 1100)
B36: บัญชีที่ระบบมีอยู่แล้วเติมให้ · บัญชีใหม่กรอกในแถวว่างด้านล่าง · ทุกบาทของบรรทัด 1100 ต้องมีบัญชีรองรับ
B37: บัญชี | C37: ธนาคาร / ช่องทาง | D37: เลขท้าย | E37: ยอดตั้งต้น
B38: ธนากร - BBL 888 | C38: กรุงเทพ | D38: 8888 | E38: 600000
B39: ธนากร - SCB | C39: ไทยพาณิชย์ | D39: 3021 | E39: 400000
F40: ← บัญชีใหม่ที่ยังไม่มีในระบบ กรอกชื่อ+ธนาคาร+ยอด
F41: ← บัญชีใหม่ที่ยังไม่มีในระบบ กรอกชื่อ+ธนาคาร+ยอด
F42: ← บัญชีใหม่ที่ยังไม่มีในระบบ กรอกชื่อ+ธนาคาร+ยอด
F43: ← บัญชีใหม่ที่ยังไม่มีในระบบ กรอกชื่อ+ธนาคาร+ยอด
F44: ← บัญชีใหม่ที่ยังไม่มีในระบบ กรอกชื่อ+ธนาคาร+ยอด
F45: ← บัญชีใหม่ที่ยังไม่มีในระบบ กรอกชื่อ+ธนาคาร+ยอด
...

Sheet BS-ธนวินท์
A1: ยอดตั้งต้นงบดุล — ธนวินท์
A2: ณ วันที่ 30/09/2026 · ราคาทุน/ตามบัญชี · ถือในชื่อบุคคล แต่ยังเป็นกองกลางของครอบครัว
A4: รหัส | B4: ชื่อบัญชี | C4: ฝั่ง | D4: หมวดในงบ | E4: ยอดตั้งต้น * | F4: หมายเหตุ / ที่มาของตัวเลข
E5: ใส่จำนวนบวกเสมอ · ไม่มียอดให้เว้นว่าง | F5: เช่น 'ยอด statement 30/09' หรือ 'ตามสัญญาเลขที่ ...'
A6: 1100 | B6: เงินสดและเงินฝากธนาคาร | C6: สินทรัพย์ | D6: สินทรัพย์หมุนเวียน
A7: 1200 | B7: ลูกหนี้ค่าเช่า | C7: สินทรัพย์ | D7: สินทรัพย์หมุนเวียน
A8: 1210 | B8: ลูกหนี้ดอกเบี้ย | C8: สินทรัพย์ | D8: สินทรัพย์หมุนเวียน
A9: 1600 | B9: เงินมัดจำจ่าย | C9: สินทรัพย์ | D9: สินทรัพย์หมุนเวียน
A10: 1300 | B10: เงินให้กู้ยืม - เงินต้น | C10: สินทรัพย์ | D10: เงินให้กู้และลงทุนตามสัญญา
A11: 1400 | B11: เงินลงทุนขายฝาก - เงินต้น | C11: สินทรัพย์ | D11: เงินให้กู้และลงทุนตามสัญญา
A12: 1410 | B12: เงินลงทุนจำนอง - เงินต้น | C12: สินทรัพย์ | D12: เงินให้กู้และลงทุนตามสัญญา
A13: 1500 | B13: อสังหาริมทรัพย์เพื่อการลงทุน | C13: สินทรัพย์ | D13: อสังหาริมทรัพย์เพื่อการลงทุน
A14: 1510 | B14: ค่ารีโนเวท (บันทึกเป็นทุน) | C14: สินทรัพย์ | D14: อสังหาริมทรัพย์เพื่อการลงทุน
A15: 1700 | B15: เงินลงทุนในหลักทรัพย์ | C15: สินทรัพย์ | D15: เงินลงทุน
A16: 1720 | B16: เงินลงทุนในทองคำและสินทรัพย์ทางเลือก | C16: สินทรัพย์ | D16: เงินลงทุน
A17: 1710 | B17: เงินลงทุนในบริษัทในเครือ | C17: สินทรัพย์ | D17: เงินลงทุน
... A26: 3300 | B26: กำไรสะสม | C26: ส่วนของเจ้าของ | D26: ส่วนของเจ้าของ
B28: รวมสินทรัพย์ | E28: =SUM(E6,E7,E8,E9,E10,E11,E12,E13,E14,E15,E16,E17,E18)
B29: รวมหนี้สิน | E29: =SUM(E19,E20,E21,E22,E23,E24)
B30: รวมส่วนของเจ้าของ | E30: =SUM(E25,E26)
B32: ตรวจ: สินทรัพย์ − หนี้สิน − ส่วนของเจ้าของ | E32: =E28-E29-E30 | F32: ต้องเป็น 0 — ถ้าไม่ใช่ ใส่ผลต่างที่ 3300 กำไรสะสม แล้วเขียนหมายเหตุไว้
B35: แยกยอดเงินสดตามบัญชี (ต้องรวมได้เท่าบรรทัด 1100)
B36: บัญชีที่ระบบมีอยู่แล้วเติมให้ · บัญชีใหม่กรอกในแถวว่างด้านล่าง · ทุกบาทของบรรทัด 1100 ต้องมีบัญชีรองรับ
B37: บัญชี | C37: ธนาคาร / ช่องทาง | D37: เลขท้าย | E37: ยอดตั้งต้น
B38: ธนวินท์ - KBANK | C38: กสิกรไทย | D38: 5520
B39: ธนวินท์ - BBL | C39: กรุงเทพ | D39: 3317
F40: ← บัญชีใหม่ที่ยังไม่มีในระบบ กรอกชื่อ+ธนาคาร+ยอด
F41: ← บัญชีใหม่ที่ยังไม่มีในระบบ กรอกชื่อ+ธนาคาร+ยอด
F42: ← บัญชีใหม่ที่ยังไม่มีในระบบ กรอกชื่อ+ธนาคาร+ยอด
F43: ← บัญชีใหม่ที่ยังไม่มีในระบบ กรอกชื่อ+ธนาคาร+ยอด
F44: ← บัญชีใหม่ที่ยังไม่มีในระบบ กรอกชื่อ+ธนาคาร+ยอด
F45: ← บัญชีใหม่ที่ยังไม่มีในระบบ กรอกชื่อ+ธนาคาร+ยอด
B46: รวมเงินสด | E46: =SUM(E38:E45) | F46: ต้องเท่ากับบรรทัด 1100 (แถว 6)
B47: ตรวจ: ผลต่างกับบรรทัด 1100 | E47: =E46-E6

Sheet BS-เบ็ญจพร
A1: ยอดตั้งต้นงบดุล — เบ็ญจพร
A2: ณ วันที่ 30/09/2026 · ราคาทุน/ตามบัญชี · ถือในชื่อบุคคล แต่ยังเป็นกองกลางของครอบครัว
A4: รหัส | B4: ชื่อบัญชี | C4: ฝั่ง | D4: หมวดในงบ | E4: ยอดตั้งต้น * | F4: หมายเหตุ / ที่มาของตัวเลข
E5: ใส่จำนวนบวกเสมอ · ไม่มียอดให้เว้นว่าง | F5: เช่น 'ยอด statement 30/09' หรือ 'ตามสัญญาเลขที่ ...'
A6: 1100 | B6: เงินสดและเงินฝากธนาคาร | C6: สินทรัพย์ | D6: สินทรัพย์หมุนเวียน
A7: 1200 | B7: ลูกหนี้ค่าเช่า | C7: สินทรัพย์ | D7: สินทรัพย์หมุนเวียน
A8: 1210 | B8: ลูกหนี้ดอกเบี้ย | C8: สินทรัพย์ | D8: สินทรัพย์หมุนเวียน
A9: 1600 | B9: เงินมัดจำจ่าย | C9: สินทรัพย์ | D9: สินทรัพย์หมุนเวียน
A10: 1300 | B10: เงินให้กู้ยืม - เงินต้น | C10: สินทรัพย์ | D10: เงินให้กู้และลงทุนตามสัญญา
A11: 1400 | B11: เงินลงทุนขายฝาก - เงินต้น | C11: สินทรัพย์ | D11: เงินให้กู้และลงทุนตามสัญญา
A12: 1410 | B12: เงินลงทุนจำนอง - เงินต้น | C12: สินทรัพย์ | D12: เงินให้กู้และลงทุนตามสัญญา
A13: 1500 | B13: อสังหาริมทรัพย์เพื่อการลงทุน | C13: สินทรัพย์ | D13: อสังหาริมทรัพย์เพื่อการลงทุน
A14: 1510 | B14: ค่ารีโนเวท (บันทึกเป็นทุน) | C14: สินทรัพย์ | D14: อสังหาริมทรัพย์เพื่อการลงทุน
A15: 1700 | B15: เงินลงทุนในหลักทรัพย์ | C15: สินทรัพย์ | D15: เงินลงทุน
A16: 1720 | B16: เงินลงทุนในทองคำและสินทรัพย์ทางเลือก | C16: สินทรัพย์ | D16: เงินลงทุน
A17: 1710 | B17: เงินลงทุนในบริษัทในเครือ | C17: สินทรัพย์ | D17: เงินลงทุน
... A26: 3300 | B26: กำไรสะสม | C26: ส่วนของเจ้าของ | D26: ส่วนของเจ้าของ
B28: รวมสินทรัพย์ | E28: =SUM(E6,E7,E8,E9,E10,E11,E12,E13,E14,E15,E16,E17,E18)
B29: รวมหนี้สิน | E29: =SUM(E19,E20,E21,E22,E23,E24)
B30: รวมส่วนของเจ้าของ | E30: =SUM(E25,E26)
B32: ตรวจ: สินทรัพย์ − หนี้สิน − ส่วนของเจ้าของ | E32: =E28-E29-E30 | F32: ต้องเป็น 0 — ถ้าไม่ใช่ ใส่ผลต่างที่ 3300 กำไรสะสม แล้วเขียนหมายเหตุไว้
B35: แยกยอดเงินสดตามบัญชี (ต้องรวมได้เท่าบรรทัด 1100)
B36: บัญชีที่ระบบมีอยู่แล้วเติมให้ · บัญชีใหม่กรอกในแถวว่างด้านล่าง · ทุกบาทของบรรทัด 1100 ต้องมีบัญชีรองรับ
B37: บัญชี | C37: ธนาคาร / ช่องทาง | D37: เลขท้าย | E37: ยอดตั้งต้น
B38: เบ็ญจพร - BBL | C38: กรุงเทพ | D38: 6045
F39: ← บัญชีใหม่ที่ยังไม่มีในระบบ กรอกชื่อ+ธนาคาร+ยอด
F40: ← บัญชีใหม่ที่ยังไม่มีในระบบ กรอกชื่อ+ธนาคาร+ยอด
F41: ← บัญชีใหม่ที่ยังไม่มีในระบบ กรอกชื่อ+ธนาคาร+ยอด
F42: ← บัญชีใหม่ที่ยังไม่มีในระบบ กรอกชื่อ+ธนาคาร+ยอด
F43: ← บัญชีใหม่ที่ยังไม่มีในระบบ กรอกชื่อ+ธนาคาร+ยอด
F44: ← บัญชีใหม่ที่ยังไม่มีในระบบ กรอกชื่อ+ธนาคาร+ยอด
B45: รวมเงินสด | E45: =SUM(E38:E44) | F45: ต้องเท่ากับบรรทัด 1100 (แถว 6)
B46: ตรวจ: ผลต่างกับบรรทัด 1100 | E46: =E45-E6

Sheet BS-สุดจิตต์
A1: ยอดตั้งต้นงบดุล — สุดจิตต์
A2: ณ วันที่ 30/09/2026 · ราคาทุน/ตามบัญชี · ถือในชื่อบุคคล แต่ยังเป็นกองกลางของครอบครัว
A4: รหัส | B4: ชื่อบัญชี | C4: ฝั่ง | D4: หมวดในงบ | E4: ยอดตั้งต้น * | F4: หมายเหตุ / ที่มาของตัวเลข
E5: ใส่จำนวนบวกเสมอ · ไม่มียอดให้เว้นว่าง | F5: เช่น 'ยอด statement 30/09' หรือ 'ตามสัญญาเลขที่ ...'
A6: 1100 | B6: เงินสดและเงินฝากธนาคาร | C6: สินทรัพย์ | D6: สินทรัพย์หมุนเวียน
A7: 1200 | B7: ลูกหนี้ค่าเช่า | C7: สินทรัพย์ | D7: สินทรัพย์หมุนเวียน
A8: 1210 | B8: ลูกหนี้ดอกเบี้ย | C8: สินทรัพย์ | D8: สินทรัพย์หมุนเวียน
A9: 1600 | B9: เงินมัดจำจ่าย | C9: สินทรัพย์ | D9: สินทรัพย์หมุนเวียน
A10: 1300 | B10: เงินให้กู้ยืม - เงินต้น | C10: สินทรัพย์ | D10: เงินให้กู้และลงทุนตามสัญญา
A11: 1400 | B11: เงินลงทุนขายฝาก - เงินต้น | C11: สินทรัพย์ | D11: เงินให้กู้และลงทุนตามสัญญา
A12: 1410 | B12: เงินลงทุนจำนอง - เงินต้น | C12: สินทรัพย์ | D12: เงินให้กู้และลงทุนตามสัญญา
A13: 1500 | B13: อสังหาริมทรัพย์เพื่อการลงทุน | C13: สินทรัพย์ | D13: อสังหาริมทรัพย์เพื่อการลงทุน
A14: 1510 | B14: ค่ารีโนเวท (บันทึกเป็นทุน) | C14: สินทรัพย์ | D14: อสังหาริมทรัพย์เพื่อการลงทุน
A15: 1700 | B15: เงินลงทุนในหลักทรัพย์ | C15: สินทรัพย์ | D15: เงินลงทุน
A16: 1720 | B16: เงินลงทุนในทองคำและสินทรัพย์ทางเลือก | C16: สินทรัพย์ | D16: เงินลงทุน
A17: 1710 | B17: เงินลงทุนในบริษัทในเครือ | C17: สินทรัพย์ | D17: เงินลงทุน
... A26: 3300 | B26: กำไรสะสม | C26: ส่วนของเจ้าของ | D26: ส่วนของเจ้าของ
B28: รวมสินทรัพย์ | E28: =SUM(E6,E7,E8,E9,E10,E11,E12,E13,E14,E15,E16,E17,E18)
B29: รวมหนี้สิน | E29: =SUM(E19,E20,E21,E22,E23,E24)
B30: รวมส่วนของเจ้าของ | E30: =SUM(E25,E26)
B32: ตรวจ: สินทรัพย์ − หนี้สิน − ส่วนของเจ้าของ | E32: =E28-E29-E30 | F32: ต้องเป็น 0 — ถ้าไม่ใช่ ใส่ผลต่างที่ 3300 กำไรสะสม แล้วเขียนหมายเหตุไว้
B35: แยกยอดเงินสดตามบัญชี (ต้องรวมได้เท่าบรรทัด 1100)
B36: บัญชีที่ระบบมีอยู่แล้วเติมให้ · บัญชีใหม่กรอกในแถวว่างด้านล่าง · ทุกบาทของบรรทัด 1100 ต้องมีบัญชีรองรับ
B37: บัญชี | C37: ธนาคาร / ช่องทาง | D37: เลขท้าย | E37: ยอดตั้งต้น
B38: สุดจิตต์ - BAY | C38: กรุงศรีอยุธยา | D38: 7702
F39: ← บัญชีใหม่ที่ยังไม่มีในระบบ กรอกชื่อ+ธนาคาร+ยอด
F40: ← บัญชีใหม่ที่ยังไม่มีในระบบ กรอกชื่อ+ธนาคาร+ยอด
F41: ← บัญชีใหม่ที่ยังไม่มีในระบบ กรอกชื่อ+ธนาคาร+ยอด
F42: ← บัญชีใหม่ที่ยังไม่มีในระบบ กรอกชื่อ+ธนาคาร+ยอด
F43: ← บัญชีใหม่ที่ยังไม่มีในระบบ กรอกชื่อ+ธนาคาร+ยอด
F44: ← บัญชีใหม่ที่ยังไม่มีในระบบ กรอกชื่อ+ธนาคาร+ยอด
B45: รวมเงินสด | E45: =SUM(E38:E44) | F45: ต้องเท่ากับบรรทัด 1100 (แถว 6)
B46: ตรวจ: ผลต่างกับบรรทัด 1100 | E46: =E45-E6

Sheet รวมทุกผู้ถือ
A1: รวมทุกผู้ถือ — SRI Family (รวมทุกชื่อ)
A2: คำนวณจากชีทของแต่ละผู้ถือ ไม่ต้องกรอก · ใช้ตรวจว่ายอดรวมกองกลางตรงกับที่ลูกพี่รู้
A4: บัญชี | B4: SRI Corporation | C4: สุธี | D4: ธนากร | E4: ธนวินท์ | F4: เบ็ญจพร | G4: สุดจิตต์ | H4: รวม
A6: รวมสินทรัพย์ | B6: ='BS-SRI Corporation'!E28 | C6: ='BS-สุธี'!E28 | D6: ='BS-ธนากร'!E28 | E6: ='BS-ธนวินท์'!E28 | F6: ='BS-เบ็ญจพร'!E28 | G6: ='BS-สุดจิตต์'!E28 | H6: =SUM(B6:G6)
A7: รวมหนี้สิน | B7: ='BS-SRI Corporation'!E29 | C7: ='BS-สุธี'!E29 | D7: ='BS-ธนากร'!E29 | E7: ='BS-ธนวินท์'!E29 | F7: ='BS-เบ็ญจพร'!E29 | G7: ='BS-สุดจิตต์'!E29 | H7: =SUM(B7:G7)
A8: รวมส่วนของเจ้าของ | B8: ='BS-SRI Corporation'!E30 | C8: ='BS-สุธี'!E30 | D8: ='BS-ธนากร'!E30 | E8: ='BS-ธนวินท์'!E30 | F8: ='BS-เบ็ญจพร'!E30 | G8: ='BS-สุดจิตต์'!E30 | H8: =SUM(B8:G8)
A10: ตรวจ: ทุกชีทลงตัวหรือยัง | B10: ='BS-SRI Corporation'!E32 | C10: ='BS-สุธี'!E32 | D10: ='BS-ธนากร'!E32 | E10: ='BS-ธนวินท์'!E32 | F10: ='BS-เบ็ญจพร'!E32 | G10: ='BS-สุดจิตต์'!E32
A12: รายการระหว่างกัน — ต้องหักกลบกันได้พอดี
A13: รวมลูกหนี้ระหว่างกัน (1310) | B13: ='BS-SRI Corporation'!E18 | C13: ='BS-สุธี'!E18 | D13: ='BS-ธนากร'!E18 | E13: ='BS-ธนวินท์'!E18 | F13: ='BS-เบ็ญจพร'!E18 | G13: ='BS-สุดจิตต์'!E18 | H13: =SUM(B13:G13)
A14: รวมเจ้าหนี้ระหว่างกัน (2310) | B14: ='BS-SRI Corporation'!E24 | C14: ='BS-สุธี'!E24 | D14: ='BS-ธนากร'!E24 | E14: ='BS-ธนวินท์'!E24 | F14: ='BS-เบ็ญจพร'!E24 | G14: ='BS-สุดจิตต์'!E24 | H14: =SUM(B14:G14)
A15: ตรวจ: ลูกหนี้ − เจ้าหนี้ ระหว่างกัน | H15: =H13-H14
A17: ถ้าช่องตรวจไม่เป็น 0 แปลว่ามีฝ่ายเดียวที่บันทึก — อีกฝ่ายลืมบันทึกหรือใส่ยอดไม่ตรง
A18: งบรวมจะตัดสองบัญชีนี้ออก ยอดกองกลางจึงต้องไม่เปลี่ยนเพราะรายการระหว่างกัน

Sheet พอร์ตลงทุน (รายล็อต)
A1: พอร์ตหลักทรัพย์ — กรอกทีละล็อต (FIFO)
A2: ลูกพี่เลือก FIFO จึงต้องรู้ว่าล็อตไหนซื้อก่อน · กรอกทุกล็อตที่ยังถืออยู่ ณ วันตัดยอด · ยอดรวม 'ต้นทุนรวม' ของแต่ละผู้ถือ ต้องเท่ากับบรรทัด 1700 ในชีทของผู้ถือคนนั้น
A4: ถือในชื่อ * | B4: ประเภท * | C4: ชื่อ/รหัส * | D4: วันที่ซื้อ * | E4: จำนวนหน่วย * | F4: ราคาต่อหน่วย * | G4: ค่าธรรมเนียมซื้อ | H4: ต้นทุนรวม | I4: สกุลเงิน *
A5: ต้องตรงกับชื่อชีทผู้ถือ | B5: หุ้นไทย / หุ้น US / ETF / กองทุน / Crypto / ทองคำ / พันธบัตร | C5: เช่น PTT, VOO, BTC | D5: FIFO ใช้วันนี้เรียงลำดับ — ถ้าไม่มีวันที่ คำนวณ FIFO ไม่ได้ | E5: ที่ยังถืออยู่ในล็อตนี้ ณ วันตัดยอด | F5: ราคาที่ซื้อจริงของล็อตนี้ ไม่ใช่ราคาเฉลี่ย | G5: รวมเป็นต้นทุน ถ้ามี | H5: คำนวณให้ = จำนวน × ราคา + ค่าธรรมเนียม | I5: THB / USD
A6: ธนากร | B6: หุ้นไทย | C6: PTT | D6: 45719 | E6: 2000 | F6: 35 | H6: =IF(E6="","",E6*F6+N(G6)) | I6: THB
A7: ธนากร | B7: ETF | C7: SET50 | D7: 45810 | E7: 100 | F7: 1000 | H7: =IF(E7="","",E7*F7+N(G7)) | I7: THB
A8: ธนากร | B8: กองทุน | C8: K-FIXED | D8: 45901 | E8: 1299 | F8: 100 | G8: 100 | H8: =IF(E8="","",E8*F8+N(G8)) | I8: THB
H9: =IF(E9="","",E9*F9+N(G9))
H10: =IF(E10="","",E10*F10+N(G10))
H11: =IF(E11="","",E11*F11+N(G11))
H12: =IF(E12="","",E12*F12+N(G12))
H13: =IF(E13="","",E13*F13+N(G13))
H14: =IF(E14="","",E14*F14+N(G14))
H15: =IF(E15="","",E15*F15+N(G15))
H16: =IF(E16="","",E16*F16+N(G16))
H17: =IF(E17="","",E17*F17+N(G17))
H18: =IF(E18="","",E18*F18+N(G18))
H19: =IF(E19="","",E19*F19+N(G19))
H20: =IF(E20="","",E20*F20+N(G20))
... H205: =IF(E205="","",E205*F205+N(G205))
